<?xml version="1.0"?>
<robot xmlns:xacro="http://www.ros.org/wiki/xacro">

  <xacro:macro name="dual_arm" params="name parent *origin">
    <link name="arm_base_link">
      <inertial>
        <origin
          xyz="0.00422660431318732 0.0234645266440117 0.245520280917725"
          rpy="0 0 0" />
        <mass
          value="5.9817893495402" />
        <inertia
          ixx="0.0763323573675301"
          ixy="-1.0074625706827E-05"
          ixz="0.00159918574737791"
          iyy="0.0636485948623856"
          iyz="2.44985620056427E-05"
          izz="0.0205452676830648" />
      </inertial>

      <visual>
        <origin xyz="0 0 0" rpy="0 0 0" />
        <geometry>
          <mesh filename="package://dual_arm_description/meshes/visual/base_link.STL" />
        </geometry>
        <material name="">
          <color rgba="0.78 0.82 0.78 1" />
        </material>
      </visual>

      <collision>
        <origin xyz="0 0 0" rpy="0 0 0" />
        <geometry>
          <mesh filename="package://dual_arm_description/meshes/collision/base_link.STL" />
        </geometry>
      </collision>
    </link>

    <joint name="arm_base_joint" type="fixed">
      <parent link="${parent}"/>
      <child link="arm_base_link"/>
      <xacro:insert_block name="origin" />
      <axis xyz="0 0 1"/>
    </joint>

    <link name="link1_right">
      <inertial>
        <origin
          xyz="-2.63462902565514E-05 0.0078456858397038 -0.0150193737682288"
          rpy="0 0 0" />
        <mass
          value="1.80177628827918" />
        <inertia
          ixx="0.00125384727993194"
          ixy="-1.9831651733611E-06"
          ixz="-5.2634557942785E-07"
          iyy="0.0012637095931909"
          iyz="-2.91199249955174E-05"
          izz="0.00129616591017272" />
      </inertial>

      <visual>
        <origin xyz="0 0 0" rpy="0 0 0" />
        <geometry>
          <mesh filename="package://dual_arm_description/meshes/visual/link1_right.STL" />
        </geometry>
        <material name="">
          <color rgba="0.55 0.6 0.55 1" />
        </material>
      </visual>

      <collision>
        <origin xyz="0 0 0" rpy="0 0 0" />
        <geometry>
          <mesh filename="package://dual_arm_description/meshes/collision/link1_right.STL" />
        </geometry>
      </collision>
    </link>

    <joint name="joint1_right" type="revolute">
      <origin xyz="-0.0078 -0.155 0.32721" rpy="1.57079632679494 -1.57079632679494 0" />
      <parent link="arm_base_link" />
      <child link="link1_right" />
      <axis xyz="0 0 1" />
      <limit
        lower="-3.14159265359"
        upper="3.14159265359"
        effort="0"
        velocity="0.436332313" />
    </joint>

    <link name="link2_right">
      <inertial>
        <origin
          xyz="-0.0184912045878147 0.00162452489349674 0.013616878292953"
          rpy="0 0 0" />
        <mass
          value="0.722746235912474" />
        <inertia
          ixx="0.00108593997275333"
          ixy="1.84897338808204E-06"
          ixz="-3.09028194254925E-05"
          iyy="0.00101515721108136"
          iyz="4.99580004142565E-06"
          izz="0.000753458785916066" />
      </inertial>

      <visual>
        <origin xyz="0 0 0" rpy="0 0 0" />
        <geometry>
          <mesh filename="package://dual_arm_description/meshes/visual/link2_right.STL" />
        </geometry>
        <material name="">
          <color rgba="0.8 0.85 0.9 1" />
        </material>
      </visual>

      <collision>
        <origin xyz="0 0 0" rpy="0 0 0" />
        <geometry>
          <mesh filename="package://dual_arm_description/meshes/collision/link2_right.STL" />
        </geometry>
      </collision>
    </link>

    <joint name="joint2_right" type="revolute">
      <origin xyz="0 0 0.054" rpy="0 1.5707963267949 0" />
      <parent link="link1_right" />
      <child link="link2_right" />
      <axis xyz="0 0 -1" />
      <limit
        lower="-1.57079632679"
        upper="1.57079632679"
        effort="0"
        velocity="0.436332313" />
    </joint>

    <link name="link3_right">
      <inertial>
        <origin
          xyz="0.00248327358203637 0.000983930202917094 0.0848422618072029"
          rpy="0 0 0" />
        <mass
          value="1.73968703689437" />
        <inertia
          ixx="0.00293287578739714"
          ixy="-4.78768415153896E-05"
          ixz="-0.000146666097337501"
          iyy="0.00269293929456573"
          iyz="-6.8741663865335E-05"
          izz="0.00158103557348051" />
      </inertial>

      <visual>
        <origin xyz="0 0 0" rpy="0 0 0" />
        <geometry>
          <mesh filename="package://dual_arm_description/meshes/visual/link3_right.STL" />
        </geometry>
        <material name="">
          <color rgba="0.8 0.85 0.9 1" />
        </material>
      </visual>

      <collision>
        <origin xyz="0 0 0" rpy="0 0 0" />
        <geometry>
          <mesh filename="package://dual_arm_description/meshes/collision/link3_right.STL" />
        </geometry>
      </collision>
    </link>
    
    <joint name="joint3_right" type="revolute">
      <origin xyz="-0.07 0 0" rpy="0 -1.57067311902631 0" />
      <parent link="link2_right" />
      <child link="link3_right" />
      <axis xyz="0 0 1" />
      <limit
        lower="-3.14159265359"
        upper="3.14159265359"
        effort="0"
        velocity="0.436332313" />
    </joint>

    <link name="link4_right">
      <inertial>
        <origin
          xyz="-7.95973702305552E-05 -0.0209082375496418 -0.00839273362275947"
          rpy="0 0 0" />
        <mass
          value="1.29895950213977" />
        <inertia
          ixx="0.00236791349815647"
          ixy="1.40731293258229E-06"
          ixz="3.26442183375437E-06"
          iyy="0.000772031871168032"
          iyz="-1.41965703385309E-05"
          izz="0.00230845350224412" />
      </inertial>

      <visual>
        <origin xyz="0 0 0" rpy="0 0 0" />
        <geometry>
          <mesh filename="package://dual_arm_description/meshes/visual/link4_right.STL" />
        </geometry>
        <material name="">
          <color rgba="0.8 0.85 0.9 1" />
        </material>
      </visual>

      <collision>
        <origin xyz="0 0 0" rpy="0 0 0" />
        <geometry>
          <mesh filename="package://dual_arm_description/meshes/collision/link4_right.STL" />
        </geometry>
      </collision>
    </link>

    <joint name="joint4_right" type="revolute">
      <origin xyz="-0.03857 0 0.23768" rpy="0 1.5707963267949 -1.5707963267949" />
      <parent link="link3_right" />
      <child link="link4_right" />
      <axis xyz="0 0 -1" />
      <limit
        lower="-2.44"
        upper="0.698131701"
        effort="0"
        velocity="0.436332313" />
    </joint>

    <link name="link5_right">
      <inertial>
        <origin
          xyz="6.30477802943119E-05 0.00086654932953717 -0.0916349080676876"
          rpy="0 0 0" />
        <mass
          value="0.943914536026674" />
        <inertia
          ixx="0.000931990246154717"
          ixy="-9.21631995424494E-06"
          ixz="-2.51581497978434E-06"
          iyy="0.000811077416357626"
          iyz="-3.8715241803587E-05"
          izz="0.000572990604772896" />
      </inertial>

      <visual>
        <origin xyz="0 0 0" rpy="0 0 0" />
        <geometry>
          <mesh filename="package://dual_arm_description/meshes/visual/link5_right.STL" />
        </geometry>
        <material name="">
          <color rgba="0.8 0.85 0.9 1" />
        </material>
      </visual>

      <collision>
        <origin xyz="0 0 0" rpy="0 0 0" />
        <geometry>
          <mesh filename="package://dual_arm_description/meshes/collision/link5_right.STL" />
        </geometry>
      </collision>
    </link>

    <joint name="joint5_right" type="revolute">
      <origin xyz="-0.175 0 0" rpy="0 -1.5707963267949 0" />
      <parent link="link4_right" />
      <child link="link5_right" />
      <axis xyz="0 0 -1" />
      <limit
        lower="-3.14159265359"
        upper="3.14159265359"
        effort="0"
        velocity="0.7853981634" />
    </joint>

    <link name="link6_right">
      <inertial>
        <origin
          xyz="0.00799400089214897 -0.00109797731745931 0.00802800673798493"
          rpy="0 0 0" />
        <mass
          value="0.87461121686283" />
        <inertia
          ixx="0.000482453783893589"
          ixy="2.78696828473613E-05"
          ixz="-1.16479121693327E-05"
          iyy="0.000519252452409952"
          iyz="2.15614721648117E-07"
          izz="0.000655950625877922" />
      </inertial>

      <visual>
        <origin xyz="0 0 0" rpy="0 0 0" />
        <geometry>
          <mesh filename="package://dual_arm_description/meshes/visual/link6_right.STL" />
        </geometry>
        <material name="">
          <color rgba="0.8 0.85 0.9 1" />
        </material>
      </visual>

      <collision>
        <origin xyz="0 0 0" rpy="0 0 0" />
        <geometry>
          <mesh filename="package://dual_arm_description/meshes/collision/link6_right.STL" />
        </geometry>
      </collision>
    </link>

    <joint name="joint6_right" type="revolute">
      <origin xyz="0 0 0.135" rpy="0 -1.5707963267949 0" />
      <parent link="link5_right" />
      <child link="link6_right" />
      <axis xyz="0 0 -1" />
      <limit
        lower="-1.308996939"
        upper="1.308996939"
        effort="0"
        velocity="0.7853981634" />
    </joint>

    <link name="link7_right">
      <inertial>
        <origin
          xyz="0.00118014491083041 -0.000343927719202997 0.00924911342229717"
          rpy="0 0 0" />
        <mass
          value="0.755429789120553" />
        <inertia
          ixx="0.000269322287342564"
          ixy="6.31271638827115E-06"
          ixz="-7.63621824391722E-08"
          iyy="0.000289179185961173"
          iyz="1.47888072820137E-08"
          izz="0.000297353940351334" />
      </inertial>

      <visual>
        <origin xyz="0 0 0" rpy="0 0 0" />
        <geometry>
          <mesh filename="package://dual_arm_description/meshes/visual/link7_right.STL" />
        </geometry>
        <material name="">
          <color rgba="0.8 0.85 0.9 1" />
        </material>
      </visual>

      <collision>
        <origin xyz="0 0 0" rpy="0 0 0" />
        <geometry>
          <mesh filename="package://dual_arm_description/meshes/collision/link7_right.STL" />
        </geometry>
      </collision>
    </link>

    <joint name="joint7_right" type="revolute">
      <origin xyz="0.067 0 0" rpy="-1.5707963267949 0 0" />
      <parent link="link6_right" />
      <child link="link7_right" />
      <axis xyz="0 0 1" />
      <limit
        lower="-1.05"
        upper="1.05"
        effort="0"
        velocity="0.7853981634" />
    </joint>

    <link name="link1_left">
      <inertial>
        <origin
          xyz="-1.38487613492444E-05 -0.00220692224137892 0.00921894631138384"
          rpy="0 0 0" />
        <mass
          value="0.519339306262197" />
        <inertia
          ixx="0.000497409399128485"
          ixy="1.04568338202191E-06"
          ixz="6.91360153863362E-08"
          iyy="0.000419809278764117"
          iyz="-1.06406718218775E-05"
          izz="0.000437145559325128" />
      </inertial>

      <visual>
        <origin xyz="0 0 0" rpy="0 0 0" />
        <geometry>
          <mesh filename="package://dual_arm_description/meshes/visual/link1_left.STL" />
        </geometry>
        <material name="">
          <color rgba="0.55 0.6 0.55 1" />
        </material>
      </visual>

      <collision>
        <origin xyz="0 0 0" rpy="0 0 0" />
        <geometry>
          <mesh filename="package://dual_arm_description/meshes/collision/link1_left.STL" />
        </geometry>
      </collision>
    </link>

    <joint name="joint1_left" type="revolute">
      <origin xyz="-0.0078 0.155 0.32721" rpy="0 -1.57079632679494 -1.57079632679494" />
      <parent link="arm_base_link" />
      <child link="link1_left" />
      <axis xyz="0 0 -1" />
      <limit
        lower="-3.14159265359"
        upper="3.14159265359"
        effort="0"
        velocity="0.436332313" />
    </joint>

    <link name="link2_left">
      <inertial>
        <origin
          xyz="0.005428504454426 0.0228357969273356 0.00572697696991797"
          rpy="0 0 0" />
        <mass
          value="0.254319595126366" />
        <inertia
          ixx="0.000415729754126609"
          ixy="1.31927673128639E-06"
          ixz="3.33686056832701E-06"
          iyy="0.000437161837114042"
          iyz="1.09061160250672E-05"
          izz="0.00033601383844043" />
      </inertial>

      <visual>
        <origin xyz="0 0 0" rpy="0 0 0" />
        <geometry>
          <mesh filename="package://dual_arm_description/meshes/visual/link2_left.STL" />
        </geometry>
        <material name="">
          <color rgba="0.8 0.85 0.9 1" />
        </material>
      </visual>

      <collision>
        <origin xyz="0 0 0" rpy="0 0 0" />
        <geometry>
          <mesh filename="package://dual_arm_description/meshes/collision/link2_left.STL" />
        </geometry>
      </collision>
    </link>

    <joint name="joint2_left" type="revolute">
      <origin xyz="0 0 0.054" rpy="0 1.5707963267949 0" />
      <parent link="link1_left" />
      <child link="link2_left" />
      <axis xyz="0 0 1" />
      <limit
        lower="-1.57079632679"
        upper="1.57079632679"
        effort="0"
        velocity="0.436332313" />
    </joint>

    <link name="link3_left">
      <inertial>
        <origin
          xyz="0.00322397114526773 0.000846637475657469 0.0985307535142525"
          rpy="0 0 0" />
        <mass
          value="0.676008865226733" />
        <inertia
          ixx="0.00175191112419296"
          ixy="-1.70722602314306E-05"
          ixz="-0.000113910532811989"
          iyy="0.00172370166259428"
          iyz="-2.23111533397412E-05"
          izz="0.000671070067083804" />
      </inertial>

      <visual>
        <origin xyz="0 0 0" rpy="0 0 0" />
        <geometry>
          <mesh filename="package://dual_arm_description/meshes/visual/link3_left.STL" />
        </geometry>
        <material name="">
          <color rgba="0.8 0.85 0.9 1" />
        </material>
      </visual>

      <collision>
        <origin xyz="0 0 0" rpy="0 0 0" />
        <geometry>
          <mesh filename="package://dual_arm_description/meshes/collision/link3_left.STL" />
        </geometry>
      </collision>
    </link>

    <joint name="joint3_left" type="revolute">
      <origin xyz="-0.07 0 0" rpy="0 -1.5707963267949 0" />
      <parent link="link2_left" />
      <child link="link3_left" />
      <axis xyz="0 0 1" />
      <limit
        lower="-3.14159265359"
        upper="3.14159265359"
        effort="0"
        velocity="0.436332313" />
    </joint>

    <link name="link4_left">
      <inertial>
        <origin
          xyz="0.000480217516793946 -0.0308900131866496 -0.00901727946172001"
          rpy="0 0 0" />
        <mass
          value="0.48418201880971" />
        <inertia
          ixx="0.00123812570090002"
          ixy="5.23140032173907E-07"
          ixz="1.19960770459451E-06"
          iyy="0.000331676843654269"
          iyz="-5.21588754606305E-06"
          izz="0.00115165867928039" />
      </inertial>

      <visual>
        <origin xyz="0 0 0" rpy="0 0 0" />
        <geometry>
          <mesh filename="package://dual_arm_description/meshes/visual/link4_left.STL" />
        </geometry>
        <material name="">
          <color rgba="0.8 0.85 0.9 1" />
        </material>
      </visual>

      <collision>
        <origin xyz="0 0 0" rpy="0 0 0" />
        <geometry>
          <mesh filename="package://dual_arm_description/meshes/collision/link4_left.STL" />
        </geometry>
      </collision>
    </link>

    <joint name="joint4_left" type="revolute">
      <origin xyz="-0.03857 0 0.23768" rpy="0 1.5707963267949 -1.5707963267949" />
      <parent link="link3_left" />
      <child link="link4_left" />
      <axis xyz="0 0 -1" />
      <limit
        lower="-2.44"
        upper="0.698131701"
        effort="0"
        velocity="0.436332313" />
    </joint>

    <link name="link5_left">
      <inertial>
        <origin
          xyz="-0.0643601135478111 0.0140250637094898 0.0715567294891026"
          rpy="0 0 0" />
        <mass
          value="0.326509644339214" />
        <inertia
          ixx="0.000455286167226561"
          ixy="-6.21144318910534E-08"
          ixz="1.5952520834946E-07"
          iyy="0.000421161448279437"
          iyz="1.33161793403503E-05"
          izz="0.000221357327075186" />
      </inertial>

      <visual>
        <origin xyz="0 0 0" rpy="0 0 0" />
        <geometry>
          <mesh filename="package://dual_arm_description/meshes/visual/link5_left.STL" />
        </geometry>
        <material name="">
          <color rgba="0.8 0.85 0.9 1" />
        </material>
      </visual>

      <collision>
        <origin xyz="0 0 0" rpy="0 0 0" />
        <geometry>
          <mesh filename="package://dual_arm_description/meshes/collision/link5_left.STL" />
        </geometry>
      </collision>
    </link>

    <joint name="joint5_left" type="revolute">
      <origin xyz="-0.175 0 0" rpy="0 -1.5707963267949 0" />
      <parent link="link4_left" />
      <child link="link5_left" />
      <axis xyz="0 0 1" />
      <limit
        lower="-3.14159265359"
        upper="3.14159265359"
        effort="0"
        velocity="0.7853981634" />
    </joint>

    <link name="link6_left">
      <inertial>
        <origin
          xyz="0.0139449905576898 -0.0635113754456291 -0.0148949144092116"
          rpy="0 0 0" />
        <mass
          value="0.300349301564401" />
        <inertia
          ixx="0.000207383702494719"
          ixy="-1.01407329092508E-05"
          ixz="4.40309165631906E-06"
          iyy="0.000272801128720996"
          iyz="3.59958116245319E-07"
          izz="0.000292271582435295" />
      </inertial>

      <visual>
        <origin xyz="0 0 0" rpy="0 0 0" />
        <geometry>
          <mesh filename="package://dual_arm_description/meshes/visual/link6_left.STL" />
        </geometry>
        <material name="">
          <color rgba="0.8 0.85 0.9 1" />
        </material>
      </visual>

      <collision>
        <origin xyz="0 0 0" rpy="0 0 0" />
        <geometry>
          <mesh filename="package://dual_arm_description/meshes/collision/link6_left.STL" />
        </geometry>
      </collision>
    </link>

    <joint name="joint6_left" type="revolute">
      <origin xyz="0 0 0.135" rpy="0 -1.5707963267949 0" />
      <parent link="link5_left" />
      <child link="link6_left" />
      <axis xyz="0 0 -1" />
      <limit
        lower="-1.308996939"
        upper="1.308996939"
        effort="0"
        velocity="0.7853981634" />
    </joint>

    <link name="link7_left">
      <inertial>
        <origin
          xyz="-0.00718537346551285 0.00450550446363263 -0.053636179982383"
          rpy="0 0 0" />
        <mass
          value="0.19917869084678" />
        <inertia
          ixx="9.43575392774057E-05"
          ixy="-7.89652831426536E-08"
          ixz="4.53006716366247E-09"
          iyy="7.82627630717662E-05"
          iyz="1.37839947237261E-07"
          izz="7.2998654079569E-05" />
      </inertial>

      <visual>
        <origin xyz="0 0 0" rpy="0 0 0" />
        <geometry>
          <mesh filename="package://dual_arm_description/meshes/visual/link7_left.STL" />
        </geometry>
        <material name="">
          <color rgba="0.8 0.85 0.9 1" />
        </material>
      </visual>

      <collision>
        <origin xyz="0 0 0" rpy="0 0 0" />
        <geometry>
          <mesh filename="package://dual_arm_description/meshes/collision/link7_left.STL" />
        </geometry>
      </collision>
    </link>

    <joint name="joint7_left" type="revolute">
      <origin xyz="0.067 0 0" rpy="-1.5707963267949 0 0" />
      <parent link="link6_left" />
      <child link="link7_left" />
      <axis xyz="0 0 1" />
      <limit
        lower="-1.05"
        upper="1.05"
        effort="0"
        velocity="0.7853981634" />
    </joint>
    
  </xacro:macro>
</robot>
